Workbook

Sheet Sheet1
B1: Company Report | O1: Report's Date: | P1: =+TODAY() -> 46076
B2: Overall | J2: Sentiment
D4: Company:
D5: Country: | K5: Nr. Analysts (atm):
D6: Sector:
D7: Industry: | J7: Period | K7: Strong Buy | L7: Buy | M7: Hold | N7: Sell | O7: Strong Sell
D8: Ticker: | J8: Now
D9: Employees: | J9: 1 Month ago
D10: Market Cap.: | J10: 2 Months ago
D11: Stock Price: | F11: (currency) | J11: 3 Months ago
D12: 52week range: | P12: Rating
D13: Dividend yield: | J13: Overall Recommendation: | P13: =+IF(OR(L13="",L13="none"),"",VLOOKUP(L13,Sheet2!$A$1:$B$6,2,FALSE))
P14: Rating
B15: Company's description | J15: Beta: | L15: -----> | M15: =IF(K15="","",IF(K15<0.8,"Low volatility",IF(K15<=1.2,"Normal volatility","High volatility"))) | P15: =+IF(M15="","",VLOOKUP(M15,Sheet2!$A$8:$B$11,2,FALSE))
J16: Notes:
J17: Earnings Dates
J18: date1
J19: date2
J20: date3
B22: Stock performance | F22: Category: | G22: (Growth/Dividends) | J22: Current Profit Margin:
J23: Current EBITDA:
J27: Risks
J28: Audit:
J29: Board:
J30: Compensation:
J31: Shareholder rights:
P32: Rating
J33: Overall: | P33: =+IF(L33="","",VLOOKUP(L33,Sheet2!$A$13:$B$23,2,FALSE))
B34: timeframe | C34: 1 week | D34: 1 month | E34: 6 months | F34: 1 year | G34: 2 years | H34: 4 years | J34: 1wk | K34: 1mo | L34: 6mo | M34: 1yr | N34: 2yr | O34: 4yr | P34: Rating
B35: % | J35: =+IF(C35="","",VLOOKUP(C35,Sheet2!$F$10:$G$15,2,TRUE)) | K35: =+IF(D35="","",VLOOKUP(D35,Sheet2!$F$10:$G$15,2,TRUE)) | L35: =+IF(E35="","",VLOOKUP(E35,Sheet2!$F$18:$G$23,2,TRUE)) | M35: =+IF(F35="","",VLOOKUP(F35,Sheet2!$F$18:$G$23,2,TRUE)) | N35: =+IF(G35="","",VLOOKUP(G35,Sheet2!$F$26:$G$31,2,TRUE)) | O35: =+IF(H35="","",VLOOKUP(H35,Sheet2!$F$26:$G$31,2,TRUE)) | P35: =+IF(J35="","",0.05*J35+0.05*K35+0.15*L35+0.15*M35+0.3*N35+0.3*O35)
B36: Financial Balance
C39: Current | D39: 2025 | E39: =+D39-1 -> 2024 | F39: =+E39-1 -> 2023 | G39: =+F39-1 -> 2022 | H39: =+G39-1 -> 2021 | J39: Average | K39: Comment | P39: Rating
B40: Cash & Equivalents | K40: =+IF(D41="","",IF(D40<0,Sheet2!$C$27,VLOOKUP(D41,Sheet2!$A$27:$C$31,3,TRUE))) | P40: =+IF(K40="","",VLOOKUP(K40,Sheet2!$C$27:$D$31,2,FALSE))
B41: % change | D41: =+IF(OR(E40="",D40="",),"",(D40-E40)/E40) | E41: =+IF(OR(F40="",E40="",),"",(E40-F40)/F40) | F41: =+IF(OR(G40="",F40="",),"",(F40-G40)/G40) | G41: =+IF(OR(H40="",G40="",),"",(G40-H40)/H40) | J41: =+IF(D41="","",AVERAGE(D41:G41)) | K41: =+IF(J41="","",IF(AND(D40<0,E40<0),Sheet2!$C$35,VLOOKUP(J41,Sheet2!$A$35:$C$39,3,TRUE))) | P41: =+IF(K41="","",VLOOKUP(K41,Sheet2!$C$35:$D$39,2,FALSE))
C43: Current | D43: =+D39 -> 2025 | E43: =+E39 -> 2024 | F43: =+F39 -> 2023 | G43: =+G39 -> 2022 | H43: =+H39 -> 2021 | J43: Average | K43: Comment | P43: Rating
B44: Inventory | K44: =+IF(D45="","",IF(D44<0,Sheet2!$C$27,VLOOKUP(D45,Sheet2!$A$27:$C$31,3,TRUE))) | P44: =+IF(K44="","",VLOOKUP(K44,Sheet2!$C$27:$D$31,2,FALSE))
B45: % change | D45: =+IF(OR(E44="",D44="",),"",(D44-E44)/E44) | E45: =+IF(OR(F44="",E44="",),"",(E44-F44)/F44) | F45: =+IF(OR(G44="",F44="",),"",(F44-G44)/G44) | G45: =+IF(OR(H44="",G44="",),"",(G44-H44)/H44) | J45: =+IF(D45="","",AVERAGE(D45:G45)) | K45: =+IF(J45="","",IF(AND(D44<0,E44<0),Sheet2!$C$35,VLOOKUP(J45,Sheet2!$A$35:$C$39,3,TRUE))) | P45: =+IF(K45="","",VLOOKUP(K45,Sheet2!$C$35:$D$39,2,FALSE))
C47: Current | D47: =+D39 -> 2025 | E47: =+E39 -> 2024 | F47: =+F39 -> 2023 | G47: =+G39 -> 2022 | H47: =+H39 -> 2021 | J47: Average
B48: Total Current Assets
B49: % change | D49: =+IF(OR(E48="",D48="",),"",(D48-E48)/E48) | E49: =+IF(OR(F48="",E48="",),"",(E48-F48)/F48) | F49: =+IF(OR(G48="",F48="",),"",(F48-G48)/G48) | G49: =+IF(OR(H48="",G48="",),"",(G48-H48)/H48) | J49: =+IF(D49="","",AVERAGE(D49:G49))
...

Sheet Sheet2
A1: Recommendation | B1: Rating | E1: Rating | F1: 1 | G1: 5
A2: strong_buy | B2: 5 | F2: min | G2: max
A3: buy | B3: 4
A4: hold | B4: 3
A5: sell | B5: 1
A6: strong_sell | B6: 0
A7: none | B7: 0
A8: Volatility | B8: Rating | F8: Stock
A9: Low volatility | B9: 5 | F9: Short-term
A10: Normal volatility | B10: 3 | F10: -1 | G10: 0
A11: High volatility | B11: 0 | F11: -0.03 | G11: 1
F12: -0.01 | G12: 2
A13: Risk | B13: Rating | F13: 0.01 | G13: 3
A14: 1 | B14: 5 | F14: 0.03 | G14: 4
A15: 2 | B15: 5 | F15: 0.05 | G15: 5
A16: 3 | B16: 4
A17: 4 | B17: 4 | F17: Medium-term
A18: 5 | B18: 3 | F18: -1 | G18: 0
A19: 6 | B19: 3 | F19: 0 | G19: 1
A20: 7 | B20: 2 | F20: 0.02 | G20: 2
A21: 8 | B21: 2 | F21: 0.06 | G21: 3
A22: 9 | B22: 1 | F22: 0.1 | G22: 4
A23: 10 | B23: 0 | F23: 0.15 | G23: 5
F25: long-term
A26: Recent Performance | F26: -1 | G26: 0
A27: -100000000000 | B27: 1 | C27: Last year's growth was mediocre or negative. | D27: 0 | F27: 0.05 | G27: 1
A28: 0.025 | B28: 2 | C28: Last year's growth was low. | D28: =+B28 -> 2 | F28: 0.1 | G28: 2
A29: 0.05 | B29: 3 | C29: Last year's growth was moderately positive. | D29: =+B29 -> 3 | F29: 0.15 | G29: 3
A30: 0.1 | B30: 4 | C30: Last year's growth was very positive. | D30: =+B30 -> 4 | F30: 0.25 | G30: 4
A31: 0.15 | B31: 5 | C31: Last year's growth was outstanding. | D31: =+B31 -> 5 | F31: 0.3 | G31: 5
A33: Overall Performance
A35: -100000000000 | B35: 1 | C35: Overall growth was mediocre or negative. | D35: 0
A36: 0.025 | B36: 2 | C36: Overall growth was low. | D36: =+B36 -> 2
A37: 0.05 | B37: 3 | C37: Overall growth was moderately positive. | D37: =+B37 -> 3
A38: 0.1 | B38: 4 | C38: Overall growth was very positive. | D38: =+B38 -> 4
A39: 0.15 | B39: 5 | C39: Overall growth was outstanding. | D39: =+B39 -> 5
A41: - > Share-Adjusted Debt to Shareholders
A42: 0 | B42: 5 | C42: Adjusted debt in relation to patrimony. | D42: =+B42 -> 5
A43: 0.8 | B43: 1 | C43: Disadjusted debt in relation to patrimony. | D43: 0
A45: 0 | B45: 5 | C45: On average, adjusted debt in relation to patrimony. | D45: =+B45 -> 5
...
